<?xml version="1.0"?>
<robot name="stereolabs_camera" xmlns:xacro="http://ros.org/wiki/xacro">


<!-- Includes -->
    <xacro:include filename="$(find zed_wrapper)/urdf/include/materials.urdf.xacro" />
    
    <!-- Arguments -->


    <xacro:arg name="camera_name"   default="zed" />
    <xacro:arg name="camera_model"  default="zed" />
    <xacro:arg name="base_frame"    default="base_link" />
    <xacro:arg name="cam_pos_x"     default="0.0" />
    <xacro:arg name="cam_pos_y"     default="0.0" />
    <xacro:arg name="cam_pos_z"     default="0.0" />
    <xacro:arg name="cam_roll"      default="0.0" />
    <xacro:arg name="cam_pitch"     default="0.0" />
    <xacro:arg name="cam_yaw"       default="0.0" />

    <!-- Properties -->
    <xacro:property name="M_PI"     value="3.1415926535897931" />
    <xacro:property name="model"    value="$(arg camera_model)" />

    <xacro:if value="${model == 'zed'}">
        <xacro:property name="baseline" value="0.12" />
    </xacro:if>
    <xacro:if value="${model == 'zedm'}">
        <xacro:property name="baseline" value="0.06" />
    </xacro:if>
    <xacro:if value="${model == 'zed2'}">
        <xacro:property name="baseline" value="0.12" />
    </xacro:if>

<!-- base_link -->
    <link name="$(arg base_frame)">
        <inertial>           
          <origin rpy="0 0 0" xyz="0 0 0"/>
          <mass value="1"/>
          <inertia ixx="0.0395416666667" ixy="0" ixz="0" iyy="0.106208333333" iyz="0" izz="0.106208333333"/>
        </inertial>
        <visual>
          <origin rpy="0 0 0" xyz="0 0 0"/>
          <geometry>
              <mesh filename="package://sentry_description/CAD/parts/assembly/Assembly v38.stl" scale="0.001 0.001 0.001"/>
          </geometry>
          <material name="silver"/>
        </visual>
        <collision>
          <origin rpy="0 0 0" xyz="0 0 0"/>
          <geometry>
              <mesh filename="package://sentry_description/CAD/parts/assembly/Assembly v38.stl" scale="0.001 0.001 0.001"/>
          </geometry>
        </collision>
    </link>


<!-- Camera Center -->
    <joint name="$(arg camera_name)_camera_center_joint" type="fixed">
        <parent link="$(arg base_frame)"/>
        <child link="$(arg camera_name)_camera_center"/>
        <!--<origin xyz="$(arg cam_pos_x) $(arg cam_pos_y) $(arg cam_pos_z)" rpy="$(arg cam_roll) $(arg cam_pitch) $(arg cam_yaw)" />-->
        <origin rpy="0 0 0" xyz="3.141592654 0 0"/>
    </joint>

    <link name="$(arg camera_name)_camera_center">
        <visual>
            <origin xyz="0 0 0" rpy="0 0 0"/>
            <geometry>
                <mesh filename="package://zed_wrapper/urdf/models/${model}.stl" />
            </geometry>
            <material name="${model}_mat" />
        </visual>
    </link>

<!-- Left Camera -->
    <joint name="$(arg camera_name)_left_camera_joint" type="fixed">
        <parent link="$(arg camera_name)_camera_center"/>
        <child link="$(arg camera_name)_left_camera_frame"/>
        <origin xyz="0 ${baseline/2} 0" rpy="3.141592654 0 0" />
    </joint>

    <link name="$(arg camera_name)_left_camera_frame" />

    <joint name="$(arg camera_name)_left_camera_optical_joint" type="fixed">
        <origin xyz="0 0 0" rpy="-${M_PI/2} 0.0 -${M_PI/2}"/>
        <parent link="$(arg camera_name)_left_camera_frame"/>
        <child link="$(arg camera_name)_left_camera_optical_frame"/>
    </joint>

    <link name="$(arg camera_name)_left_camera_optical_frame"/>

<!-- Right Camera -->
    <joint name="$(arg camera_name)_right_camera_joint" type="fixed">
        <parent link="$(arg camera_name)_camera_center"/>
        <child link="$(arg camera_name)_right_camera_frame"/>
        <origin xyz="0 -${baseline/2} 0" rpy="0 0 0" />
    </joint>

    <link name="$(arg camera_name)_right_camera_frame" />

    <joint name="$(arg camera_name)_right_camera_optical_joint" type="fixed">
        <origin xyz="0 0 0" rpy="-${M_PI/2} 0.0 -${M_PI/2}"/>
        <parent link="$(arg camera_name)_right_camera_frame"/>
        <child link="$(arg camera_name)_right_camera_optical_frame"/>
    </joint>

    <link name="$(arg camera_name)_right_camera_optical_frame"/>

<!-- ZED2 Sensors -->
    <xacro:if value="${model == 'zed2'}">
        <joint name="$(arg camera_name)_mag_joint" type="fixed">
            <parent link="$(arg camera_name)_camera_center"/>
            <child link="$(arg camera_name)_mag_link"/>
            <origin xyz="0 0 0" rpy="3.141592654 0 0" />
        </joint>

        <link name="$(arg camera_name)_mag_link" />

        <joint name="$(arg camera_name)_baro_joint" type="fixed">
            <parent link="$(arg camera_name)_camera_center"/>
            <child link="$(arg camera_name)_baro_link"/>
            <origin xyz="0 0 0" rpy="3.141592654 0 0" />
        </joint>

        <link name="$(arg camera_name)_baro_link" />

        <joint name="$(arg camera_name)_temp_left_joint" type="fixed">
            <parent link="$(arg camera_name)_left_camera_frame"/>
            <child link="$(arg camera_name)_temp_left_link"/>
            <origin xyz="0 0 0" rpy="3.141592654 0 0" />
        </joint>

        <link name="$(arg camera_name)_temp_left_link" />

        <joint name="$(arg camera_name)_temp_right_joint" type="fixed">
            <parent link="$(arg camera_name)_right_camera_frame"/>
            <child link="$(arg camera_name)_temp_right_link"/>
            <origin xyz="0 0 0" rpy="3.141592654 0 0" />
        </joint>

        <link name="$(arg camera_name)_temp_right_link" />
    </xacro:if>

    <!-- Wheel Link -->
  <!-- Both wheels can be referenced from the same STL -->
  <link name="left_wheel">
    <inertial>
      <!--<origin rpy="0 0 0" xyz="-0.16605823931256913 -0.20000099435655025 0.0635760224098007"/>-->
      <origin rpy="0 0 0" xyz="0 0 0"/>
      <mass value="1"/>
      <inertia ixx="0.001218" ixy="-0.0" ixz="0.0" iyy="0.000635" iyz="-0.0" izz="0.000635"/>
    </inertial>
    <visual>
      <origin rpy="0 0 0" xyz="0 0 0"/>
      <geometry>
        <mesh filename="package://sentry_description/CAD/parts/wheel/Tire v5.stl" scale="0.001 0.001 0.001"/>
      </geometry>
      <material name="silver"/>
    </visual>
    <collision>
      <origin rpy="0 0 0" xyz="0 0 0"/>
      <geometry>
        <mesh filename="package://sentry_description/CAD/parts/wheel/Tire v5.stl" scale="0.001 0.001 0.001"/>
      </geometry>
    </collision>
  </link>

  <link name="right_wheel">
      <inertial>
      <!--<origin rpy="0 0 0" xyz="-0.16605823931256913 -0.20000099435655025 0.0635760224098007"/>-->
      <origin rpy="0 0 0" xyz="0 0 0"/>
      <mass value="1"/>
      <inertia ixx="0.001218" ixy="-0.0" ixz="0.0" iyy="0.000635" iyz="-0.0" izz="0.000635"/>
    </inertial>
    <visual>
      <origin rpy="0 0 0" xyz="0 0 0"/>
      <geometry>
        <mesh filename="package://sentry_description/CAD/parts/wheel/Tire v5.stl" scale="0.001 0.001 0.001"/>
      </geometry>
      <material name="silver"/>
    </visual>
    <collision>
      <origin rpy="0 0 0" xyz="0 0 0"/>
      <geometry>
        <mesh filename="package://sentry_description/CAD/parts/wheel/Tire v5.stl" scale="0.001 0.001 0.001"/>
      </geometry>
    </collision>
  </link>
  
   <!--Wheel Joints-->
  <joint name="left_wheel_joint" type="continuous">
    <origin rpy="0 0 0" xyz="-0.2 0 0"/> 
    <parent link="$(arg base_frame)" />
    <child link="left_wheel"/>
    <axis xyz="1.0 0.0 0.0"/>
    <limit effort="10000" velocity="1000"/>
    <joint_properties damping="1.0" friction="1.0"/>
  </joint>

  <joint name="right_wheel_joint" type="continuous">
  <!-- yaw set to 3.14159 to flip the wheel and align it properly-->
    <origin rpy="0 0 0" xyz="0.2 0 0"/>
    <parent link="$(arg base_frame)" />
    <child link="right_wheel"/>
    <axis xyz="-1.0 0.0 0.0"/>
    <limit effort="10000" velocity="1000"/>
    <joint_properties damping="1.0" friction="1.0"/>
  </joint>

</robot>